{
 "cells": [
  {
   "cell_type": "markdown",
   "metadata": {},
   "source": [
    "# Malayalam Films : A Data Analysis Experiment\n",
    "\n",
    "### 1. Data ingestion\n",
    "    \n",
    "Data extraction by web scraping through wikipedia links. "
   ]
  },
  {
   "cell_type": "code",
   "execution_count": 7,
   "metadata": {},
   "outputs": [],
   "source": [
    "#imprting all libraries required\n",
    "\n",
    "import requests\n",
    "from bs4 import BeautifulSoup\n",
    "import pandas as pd\n",
    "import html5lib\n",
    "import numpy as np\n",
    "from datetime import datetime\n"
   ]
  },
  {
   "cell_type": "code",
   "execution_count": 8,
   "metadata": {},
   "outputs": [],
   "source": [
    "FEATURES = ['day','month','year' , 'title', 'director','producer', 'cast', 'genre','story','screenplay','gross','distributor',\n",
    "            'composer','lyricist','no_of_songs', 'singers','editor','cinematography','banner','dialogue',\n",
    "            'art_direction','running_time','budget','state_awards','national_awards','plot','imdb_rating',\n",
    "            'imdb_vote_count']\n",
    "#function to get the table in wikilink\n",
    "def get_table(url,idname,classname):\n",
    "\n",
    "    url = requests.get(url).text\n",
    "    soup = BeautifulSoup(url,\"lxml\")\n",
    "    if idname:\n",
    "        table = soup.find(\"table\",{\"id\":idname})\n",
    "    else:\n",
    "        table = soup.find(\"table\",{\"class\":classname})\n",
    "\n",
    "    return str(table)\n",
    "\n",
    "#Convert string to date\n",
    "def convert2date(date_text):\n",
    "    res = datetime.strptime(date_text, '%b %d %Y').date()\n",
    "    return res\n"
   ]
  },
  {
   "cell_type": "code",
   "execution_count": 9,
   "metadata": {},
   "outputs": [],
   "source": [
    "def pattern(data,flag):\n",
    "    \n",
    "    if flag:\n",
    "        data.insert(5,\"genre\",np.nan)\n",
    "        data.columns = [0,1,2,3,4,5,6]\n",
    "    data = data.reset_index()\n",
    "    df1=data[data[6].notnull()]\n",
    "    \n",
    "    df2 =data[data[6].isnull()]\n",
    "    \n",
    "    df3 = df2[df2[0].str.isnumeric()]\n",
    "    df3.insert(1,\"month\",np.nan)\n",
    "    df3.columns = ['index', 0, 1, 2, 3, 4, 5, 6,7]\n",
    "    \n",
    "    df4 = df2[df2[0].str.isalpha()]\n",
    "    df4.insert(1,\"month\",np.nan)\n",
    "    df4.insert(2,\"day\",np.nan)\n",
    "    df4.columns =['index',0, 1, 2, 3, 4,5,6,7,8]\n",
    "    \n",
    "    frames = [df1,df3,df4]\n",
    "    result = pd.concat(frames).sort_values(by=['index'])\n",
    "    result = result.fillna(method='ffill')\n",
    "    result = result.drop([\"index\",7,8],1)\n",
    "    columns = ['Month', 'Date', 'Title', 'Director', 'Cast', 'Genre',\"Ref\"]\n",
    "    result.columns = columns\n",
    "    result = result.drop(0,0)\n",
    "    result = result.drop(\"Ref\",1)\n",
    "\n",
    "\n",
    "    release_date =  result.iloc[:,0].apply(lambda x: x[:3]).map(str) + \" \" + result.iloc[:,1] + \" \" + year\n",
    "    release_date = release_date.apply(lambda x:convert2date(x))\n",
    "    result.insert(0,'release_date',release_date)\n",
    "    result =result.drop([\"Month\",\"Date\"],1)\n",
    "    return result\n",
    "\n",
    "    \n",
    "\n"
   ]
  },
  {
   "cell_type": "code",
   "execution_count": 10,
   "metadata": {},
   "outputs": [],
   "source": [
    "def get_data_wiki(year):\n",
    "    url =\"https://en.wikipedia.org/wiki/List_of_Malayalam_films_of_\"+year\n",
    "    t = get_table(url,None,\"wikitable\")\n",
    "    data = pd.read_html(t)[0]\n",
    "    return data\n",
    "    "
   ]
  },
  {
   "cell_type": "code",
   "execution_count": 25,
   "metadata": {},
   "outputs": [
    {
     "data": {
      "text/plain": [
       "(12, 8)"
      ]
     },
     "execution_count": 25,
     "metadata": {},
     "output_type": "execute_result"
    }
   ],
   "source": [
    "data = get_data_wiki(\"1961\")\n",
    "data.shape\n"
   ]
  },
  {
   "cell_type": "code",
   "execution_count": 26,
   "metadata": {
    "scrolled": false
   },
   "outputs": [
    {
     "data": {
      "text/html": [
       "<div>\n",
       "<style scoped>\n",
       "    .dataframe tbody tr th:only-of-type {\n",
       "        vertical-align: middle;\n",
       "    }\n",
       "\n",
       "    .dataframe tbody tr th {\n",
       "        vertical-align: top;\n",
       "    }\n",
       "\n",
       "    .dataframe thead th {\n",
       "        text-align: right;\n",
       "    }\n",
       "</style>\n",
       "<table border=\"1\" class=\"dataframe\">\n",
       "  <thead>\n",
       "    <tr style=\"text-align: right;\">\n",
       "      <th></th>\n",
       "      <th>0</th>\n",
       "      <th>1</th>\n",
       "      <th>2</th>\n",
       "      <th>3</th>\n",
       "      <th>4</th>\n",
       "      <th>5</th>\n",
       "      <th>6</th>\n",
       "      <th>7</th>\n",
       "    </tr>\n",
       "  </thead>\n",
       "  <tbody>\n",
       "    <tr>\n",
       "      <th>0</th>\n",
       "      <td>Opening</td>\n",
       "      <td>Sl.no.</td>\n",
       "      <td>Film</td>\n",
       "      <td>Cast</td>\n",
       "      <td>Director</td>\n",
       "      <td>Music director</td>\n",
       "      <td>Notes</td>\n",
       "      <td>NaN</td>\n",
       "    </tr>\n",
       "    <tr>\n",
       "      <th>1</th>\n",
       "      <td>JAN</td>\n",
       "      <td>NaN</td>\n",
       "      <td>NaN</td>\n",
       "      <td>NaN</td>\n",
       "      <td>NaN</td>\n",
       "      <td>NaN</td>\n",
       "      <td>NaN</td>\n",
       "      <td>NaN</td>\n",
       "    </tr>\n",
       "    <tr>\n",
       "      <th>2</th>\n",
       "      <td>28</td>\n",
       "      <td>1</td>\n",
       "      <td>Christmas Rathri</td>\n",
       "      <td>T. K. Balachandran, Thikkurissi Sukumaran Nair</td>\n",
       "      <td>P. Subramaniam</td>\n",
       "      <td>Br. Lakshmanan</td>\n",
       "      <td>NaN</td>\n",
       "      <td>NaN</td>\n",
       "    </tr>\n",
       "    <tr>\n",
       "      <th>3</th>\n",
       "      <td>APR</td>\n",
       "      <td>14</td>\n",
       "      <td>2</td>\n",
       "      <td>Ummini Thanka</td>\n",
       "      <td>Sukumari, Kedamangalam Sadanandan</td>\n",
       "      <td>G. Viswanath</td>\n",
       "      <td>V. Dakshinamoorthy</td>\n",
       "      <td>NaN</td>\n",
       "    </tr>\n",
       "    <tr>\n",
       "      <th>4</th>\n",
       "      <td>AUG</td>\n",
       "      <td>24</td>\n",
       "      <td>3</td>\n",
       "      <td>Kandam Bacha Kotte</td>\n",
       "      <td>Thikkurissy Sukumaran Nair, Prem Nawas</td>\n",
       "      <td>T. R. Sundaram</td>\n",
       "      <td>Baburaj</td>\n",
       "      <td>Certificate of Merit for Second Best Feature Film</td>\n",
       "    </tr>\n",
       "  </tbody>\n",
       "</table>\n",
       "</div>"
      ],
      "text/plain": [
       "         0       1                 2  \\\n",
       "0  Opening  Sl.no.              Film   \n",
       "1      JAN     NaN               NaN   \n",
       "2       28       1  Christmas Rathri   \n",
       "3      APR      14                 2   \n",
       "4      AUG      24                 3   \n",
       "\n",
       "                                                3  \\\n",
       "0                                            Cast   \n",
       "1                                             NaN   \n",
       "2  T. K. Balachandran, Thikkurissi Sukumaran Nair   \n",
       "3                                   Ummini Thanka   \n",
       "4                              Kandam Bacha Kotte   \n",
       "\n",
       "                                        4               5                   6  \\\n",
       "0                                Director  Music director               Notes   \n",
       "1                                     NaN             NaN                 NaN   \n",
       "2                          P. Subramaniam  Br. Lakshmanan                 NaN   \n",
       "3       Sukumari, Kedamangalam Sadanandan    G. Viswanath  V. Dakshinamoorthy   \n",
       "4  Thikkurissy Sukumaran Nair, Prem Nawas  T. R. Sundaram             Baburaj   \n",
       "\n",
       "                                                   7  \n",
       "0                                                NaN  \n",
       "1                                                NaN  \n",
       "2                                                NaN  \n",
       "3                                                NaN  \n",
       "4  Certificate of Merit for Second Best Feature Film  "
      ]
     },
     "execution_count": 26,
     "metadata": {},
     "output_type": "execute_result"
    }
   ],
   "source": [
    "#data = data.reset_index()\n",
    "data.head()"
   ]
  },
  {
   "cell_type": "code",
   "execution_count": 13,
   "metadata": {},
   "outputs": [
    {
     "name": "stderr",
     "output_type": "stream",
     "text": [
      "ERROR:root:Internal Python error in the inspect module.\n",
      "Below is the traceback from this internal error.\n",
      "\n",
      "ERROR:root:Internal Python error in the inspect module.\n",
      "Below is the traceback from this internal error.\n",
      "\n",
      "ERROR:root:Internal Python error in the inspect module.\n",
      "Below is the traceback from this internal error.\n",
      "\n"
     ]
    },
    {
     "name": "stdout",
     "output_type": "stream",
     "text": [
      "Traceback (most recent call last):\n",
      "  File \"/Users/fauxcomrade/anaconda3/lib/python3.6/site-packages/pandas/core/indexes/base.py\", line 2525, in get_loc\n",
      "    return self._engine.get_loc(key)\n",
      "  File \"pandas/_libs/index.pyx\", line 117, in pandas._libs.index.IndexEngine.get_loc\n",
      "  File \"pandas/_libs/index.pyx\", line 139, in pandas._libs.index.IndexEngine.get_loc\n",
      "  File \"pandas/_libs/hashtable_class_helper.pxi\", line 1265, in pandas._libs.hashtable.PyObjectHashTable.get_item\n",
      "  File \"pandas/_libs/hashtable_class_helper.pxi\", line 1273, in pandas._libs.hashtable.PyObjectHashTable.get_item\n",
      "KeyError: 6\n",
      "\n",
      "During handling of the above exception, another exception occurred:\n",
      "\n",
      "Traceback (most recent call last):\n",
      "  File \"/Users/fauxcomrade/anaconda3/lib/python3.6/site-packages/IPython/core/interactiveshell.py\", line 2910, in run_code\n",
      "    exec(code_obj, self.user_global_ns, self.user_ns)\n",
      "  File \"<ipython-input-13-c357c7a3cd4d>\", line 1, in <module>\n",
      "    df1=data[data[6].notnull()]\n",
      "  File \"/Users/fauxcomrade/anaconda3/lib/python3.6/site-packages/pandas/core/frame.py\", line 2139, in __getitem__\n",
      "    return self._getitem_column(key)\n",
      "  File \"/Users/fauxcomrade/anaconda3/lib/python3.6/site-packages/pandas/core/frame.py\", line 2146, in _getitem_column\n",
      "    return self._get_item_cache(key)\n",
      "  File \"/Users/fauxcomrade/anaconda3/lib/python3.6/site-packages/pandas/core/generic.py\", line 1842, in _get_item_cache\n",
      "    values = self._data.get(item)\n",
      "  File \"/Users/fauxcomrade/anaconda3/lib/python3.6/site-packages/pandas/core/internals.py\", line 3843, in get\n",
      "    loc = self.items.get_loc(item)\n",
      "  File \"/Users/fauxcomrade/anaconda3/lib/python3.6/site-packages/pandas/core/indexes/base.py\", line 2527, in get_loc\n",
      "    return self._engine.get_loc(self._maybe_cast_indexer(key))\n",
      "  File \"pandas/_libs/index.pyx\", line 117, in pandas._libs.index.IndexEngine.get_loc\n",
      "  File \"pandas/_libs/index.pyx\", line 139, in pandas._libs.index.IndexEngine.get_loc\n",
      "  File \"pandas/_libs/hashtable_class_helper.pxi\", line 1265, in pandas._libs.hashtable.PyObjectHashTable.get_item\n",
      "  File \"pandas/_libs/hashtable_class_helper.pxi\", line 1273, in pandas._libs.hashtable.PyObjectHashTable.get_item\n",
      "KeyError: 6\n",
      "\n",
      "During handling of the above exception, another exception occurred:\n",
      "\n",
      "Traceback (most recent call last):\n",
      "  File \"/Users/fauxcomrade/anaconda3/lib/python3.6/site-packages/IPython/core/interactiveshell.py\", line 1828, in showtraceback\n",
      "    stb = value._render_traceback_()\n",
      "AttributeError: 'KeyError' object has no attribute '_render_traceback_'\n",
      "\n",
      "During handling of the above exception, another exception occurred:\n",
      "\n",
      "Traceback (most recent call last):\n",
      "  File \"/Users/fauxcomrade/anaconda3/lib/python3.6/site-packages/IPython/core/ultratb.py\", line 1090, in get_records\n",
      "    return _fixed_getinnerframes(etb, number_of_lines_of_context, tb_offset)\n",
      "  File \"/Users/fauxcomrade/anaconda3/lib/python3.6/site-packages/IPython/core/ultratb.py\", line 311, in wrapped\n",
      "    return f(*args, **kwargs)\n",
      "  File \"/Users/fauxcomrade/anaconda3/lib/python3.6/site-packages/IPython/core/ultratb.py\", line 345, in _fixed_getinnerframes\n",
      "    records = fix_frame_records_filenames(inspect.getinnerframes(etb, context))\n",
      "  File \"/Users/fauxcomrade/anaconda3/lib/python3.6/inspect.py\", line 1483, in getinnerframes\n",
      "    frameinfo = (tb.tb_frame,) + getframeinfo(tb, context)\n",
      "  File \"/Users/fauxcomrade/anaconda3/lib/python3.6/inspect.py\", line 1441, in getframeinfo\n",
      "    filename = getsourcefile(frame) or getfile(frame)\n",
      "  File \"/Users/fauxcomrade/anaconda3/lib/python3.6/inspect.py\", line 696, in getsourcefile\n",
      "    if getattr(getmodule(object, filename), '__loader__', None) is not None:\n",
      "  File \"/Users/fauxcomrade/anaconda3/lib/python3.6/inspect.py\", line 733, in getmodule\n",
      "    if ismodule(module) and hasattr(module, '__file__'):\n",
      "  File \"/Users/fauxcomrade/anaconda3/lib/python3.6/site-packages/py/_vendored_packages/apipkg.py\", line 195, in __getattribute__\n",
      "    return getattr(getmod(), name)\n",
      "  File \"/Users/fauxcomrade/anaconda3/lib/python3.6/site-packages/py/_vendored_packages/apipkg.py\", line 179, in getmod\n",
      "    x = importobj(modpath, None)\n",
      "  File \"/Users/fauxcomrade/anaconda3/lib/python3.6/site-packages/py/_vendored_packages/apipkg.py\", line 69, in importobj\n",
      "    module = __import__(modpath, None, None, ['__doc__'])\n",
      "  File \"/Users/fauxcomrade/anaconda3/lib/python3.6/site-packages/pytest.py\", line 13, in <module>\n",
      "    from _pytest.fixtures import fixture, yield_fixture\n",
      "  File \"/Users/fauxcomrade/anaconda3/lib/python3.6/site-packages/_pytest/fixtures.py\", line 842, in <module>\n",
      "    class FixtureFunctionMarker(object):\n",
      "  File \"/Users/fauxcomrade/anaconda3/lib/python3.6/site-packages/_pytest/fixtures.py\", line 844, in FixtureFunctionMarker\n",
      "    params = attr.ib(convert=attr.converters.optional(tuple))\n",
      "TypeError: attrib() got an unexpected keyword argument 'convert'\n",
      "Traceback (most recent call last):\n",
      "  File \"/Users/fauxcomrade/anaconda3/lib/python3.6/site-packages/pandas/core/indexes/base.py\", line 2525, in get_loc\n",
      "    return self._engine.get_loc(key)\n",
      "  File \"pandas/_libs/index.pyx\", line 117, in pandas._libs.index.IndexEngine.get_loc\n",
      "  File \"pandas/_libs/index.pyx\", line 139, in pandas._libs.index.IndexEngine.get_loc\n",
      "  File \"pandas/_libs/hashtable_class_helper.pxi\", line 1265, in pandas._libs.hashtable.PyObjectHashTable.get_item\n",
      "  File \"pandas/_libs/hashtable_class_helper.pxi\", line 1273, in pandas._libs.hashtable.PyObjectHashTable.get_item\n",
      "KeyError: 6\n",
      "\n",
      "During handling of the above exception, another exception occurred:\n",
      "\n",
      "Traceback (most recent call last):\n",
      "  File \"/Users/fauxcomrade/anaconda3/lib/python3.6/site-packages/IPython/core/interactiveshell.py\", line 2910, in run_code\n",
      "    exec(code_obj, self.user_global_ns, self.user_ns)\n",
      "  File \"<ipython-input-13-c357c7a3cd4d>\", line 1, in <module>\n",
      "    df1=data[data[6].notnull()]\n",
      "  File \"/Users/fauxcomrade/anaconda3/lib/python3.6/site-packages/pandas/core/frame.py\", line 2139, in __getitem__\n",
      "    return self._getitem_column(key)\n",
      "  File \"/Users/fauxcomrade/anaconda3/lib/python3.6/site-packages/pandas/core/frame.py\", line 2146, in _getitem_column\n",
      "    return self._get_item_cache(key)\n",
      "  File \"/Users/fauxcomrade/anaconda3/lib/python3.6/site-packages/pandas/core/generic.py\", line 1842, in _get_item_cache\n",
      "    values = self._data.get(item)\n",
      "  File \"/Users/fauxcomrade/anaconda3/lib/python3.6/site-packages/pandas/core/internals.py\", line 3843, in get\n",
      "    loc = self.items.get_loc(item)\n",
      "  File \"/Users/fauxcomrade/anaconda3/lib/python3.6/site-packages/pandas/core/indexes/base.py\", line 2527, in get_loc\n",
      "    return self._engine.get_loc(self._maybe_cast_indexer(key))\n",
      "  File \"pandas/_libs/index.pyx\", line 117, in pandas._libs.index.IndexEngine.get_loc\n",
      "  File \"pandas/_libs/index.pyx\", line 139, in pandas._libs.index.IndexEngine.get_loc\n",
      "  File \"pandas/_libs/hashtable_class_helper.pxi\", line 1265, in pandas._libs.hashtable.PyObjectHashTable.get_item\n",
      "  File \"pandas/_libs/hashtable_class_helper.pxi\", line 1273, in pandas._libs.hashtable.PyObjectHashTable.get_item\n",
      "KeyError: 6\n",
      "\n",
      "During handling of the above exception, another exception occurred:\n",
      "\n",
      "Traceback (most recent call last):\n",
      "  File \"/Users/fauxcomrade/anaconda3/lib/python3.6/site-packages/IPython/core/interactiveshell.py\", line 1828, in showtraceback\n",
      "    stb = value._render_traceback_()\n",
      "AttributeError: 'KeyError' object has no attribute '_render_traceback_'\n",
      "\n",
      "During handling of the above exception, another exception occurred:\n",
      "\n",
      "Traceback (most recent call last):\n",
      "  File \"/Users/fauxcomrade/anaconda3/lib/python3.6/site-packages/IPython/core/interactiveshell.py\", line 2850, in run_ast_nodes\n",
      "    if self.run_code(code, result):\n",
      "  File \"/Users/fauxcomrade/anaconda3/lib/python3.6/site-packages/IPython/core/interactiveshell.py\", line 2927, in run_code\n",
      "    self.showtraceback(running_compiled_code=True)\n",
      "  File \"/Users/fauxcomrade/anaconda3/lib/python3.6/site-packages/IPython/core/interactiveshell.py\", line 1831, in showtraceback\n",
      "    value, tb, tb_offset=tb_offset)\n",
      "  File \"/Users/fauxcomrade/anaconda3/lib/python3.6/site-packages/IPython/core/ultratb.py\", line 1371, in structured_traceback\n",
      "    self, etype, value, tb, tb_offset, number_of_lines_of_context)\n",
      "  File \"/Users/fauxcomrade/anaconda3/lib/python3.6/site-packages/IPython/core/ultratb.py\", line 1279, in structured_traceback\n",
      "    self, etype, value, tb, tb_offset, number_of_lines_of_context\n",
      "  File \"/Users/fauxcomrade/anaconda3/lib/python3.6/site-packages/IPython/core/ultratb.py\", line 1140, in structured_traceback\n",
      "    formatted_exceptions += self.prepare_chained_exception_message(evalue.__cause__)\n",
      "TypeError: must be str, not list\n",
      "\n",
      "During handling of the above exception, another exception occurred:\n",
      "\n",
      "Traceback (most recent call last):\n",
      "  File \"/Users/fauxcomrade/anaconda3/lib/python3.6/site-packages/IPython/core/interactiveshell.py\", line 1828, in showtraceback\n",
      "    stb = value._render_traceback_()\n",
      "AttributeError: 'TypeError' object has no attribute '_render_traceback_'\n",
      "\n",
      "During handling of the above exception, another exception occurred:\n",
      "\n",
      "Traceback (most recent call last):\n",
      "  File \"/Users/fauxcomrade/anaconda3/lib/python3.6/site-packages/IPython/core/ultratb.py\", line 1090, in get_records\n",
      "    return _fixed_getinnerframes(etb, number_of_lines_of_context, tb_offset)\n",
      "  File \"/Users/fauxcomrade/anaconda3/lib/python3.6/site-packages/IPython/core/ultratb.py\", line 311, in wrapped\n",
      "    return f(*args, **kwargs)\n",
      "  File \"/Users/fauxcomrade/anaconda3/lib/python3.6/site-packages/IPython/core/ultratb.py\", line 345, in _fixed_getinnerframes\n",
      "    records = fix_frame_records_filenames(inspect.getinnerframes(etb, context))\n",
      "  File \"/Users/fauxcomrade/anaconda3/lib/python3.6/inspect.py\", line 1483, in getinnerframes\n",
      "    frameinfo = (tb.tb_frame,) + getframeinfo(tb, context)\n",
      "  File \"/Users/fauxcomrade/anaconda3/lib/python3.6/inspect.py\", line 1441, in getframeinfo\n",
      "    filename = getsourcefile(frame) or getfile(frame)\n",
      "  File \"/Users/fauxcomrade/anaconda3/lib/python3.6/inspect.py\", line 696, in getsourcefile\n",
      "    if getattr(getmodule(object, filename), '__loader__', None) is not None:\n",
      "  File \"/Users/fauxcomrade/anaconda3/lib/python3.6/inspect.py\", line 733, in getmodule\n",
      "    if ismodule(module) and hasattr(module, '__file__'):\n",
      "  File \"/Users/fauxcomrade/anaconda3/lib/python3.6/site-packages/py/_vendored_packages/apipkg.py\", line 195, in __getattribute__\n",
      "    return getattr(getmod(), name)\n",
      "  File \"/Users/fauxcomrade/anaconda3/lib/python3.6/site-packages/py/_vendored_packages/apipkg.py\", line 179, in getmod\n",
      "    x = importobj(modpath, None)\n",
      "  File \"/Users/fauxcomrade/anaconda3/lib/python3.6/site-packages/py/_vendored_packages/apipkg.py\", line 69, in importobj\n",
      "    module = __import__(modpath, None, None, ['__doc__'])\n",
      "  File \"/Users/fauxcomrade/anaconda3/lib/python3.6/site-packages/pytest.py\", line 13, in <module>\n",
      "    from _pytest.fixtures import fixture, yield_fixture\n",
      "  File \"/Users/fauxcomrade/anaconda3/lib/python3.6/site-packages/_pytest/fixtures.py\", line 842, in <module>\n",
      "    class FixtureFunctionMarker(object):\n",
      "  File \"/Users/fauxcomrade/anaconda3/lib/python3.6/site-packages/_pytest/fixtures.py\", line 844, in FixtureFunctionMarker\n",
      "    params = attr.ib(convert=attr.converters.optional(tuple))\n",
      "TypeError: attrib() got an unexpected keyword argument 'convert'\n",
      "Traceback (most recent call last):\n",
      "  File \"/Users/fauxcomrade/anaconda3/lib/python3.6/site-packages/pandas/core/indexes/base.py\", line 2525, in get_loc\n",
      "    return self._engine.get_loc(key)\n",
      "  File \"pandas/_libs/index.pyx\", line 117, in pandas._libs.index.IndexEngine.get_loc\n",
      "  File \"pandas/_libs/index.pyx\", line 139, in pandas._libs.index.IndexEngine.get_loc\n",
      "  File \"pandas/_libs/hashtable_class_helper.pxi\", line 1265, in pandas._libs.hashtable.PyObjectHashTable.get_item\n",
      "  File \"pandas/_libs/hashtable_class_helper.pxi\", line 1273, in pandas._libs.hashtable.PyObjectHashTable.get_item\n",
      "KeyError: 6\n",
      "\n",
      "During handling of the above exception, another exception occurred:\n",
      "\n",
      "Traceback (most recent call last):\n",
      "  File \"/Users/fauxcomrade/anaconda3/lib/python3.6/site-packages/IPython/core/interactiveshell.py\", line 2910, in run_code\n",
      "    exec(code_obj, self.user_global_ns, self.user_ns)\n",
      "  File \"<ipython-input-13-c357c7a3cd4d>\", line 1, in <module>\n",
      "    df1=data[data[6].notnull()]\n",
      "  File \"/Users/fauxcomrade/anaconda3/lib/python3.6/site-packages/pandas/core/frame.py\", line 2139, in __getitem__\n",
      "    return self._getitem_column(key)\n",
      "  File \"/Users/fauxcomrade/anaconda3/lib/python3.6/site-packages/pandas/core/frame.py\", line 2146, in _getitem_column\n",
      "    return self._get_item_cache(key)\n",
      "  File \"/Users/fauxcomrade/anaconda3/lib/python3.6/site-packages/pandas/core/generic.py\", line 1842, in _get_item_cache\n",
      "    values = self._data.get(item)\n",
      "  File \"/Users/fauxcomrade/anaconda3/lib/python3.6/site-packages/pandas/core/internals.py\", line 3843, in get\n",
      "    loc = self.items.get_loc(item)\n",
      "  File \"/Users/fauxcomrade/anaconda3/lib/python3.6/site-packages/pandas/core/indexes/base.py\", line 2527, in get_loc\n",
      "    return self._engine.get_loc(self._maybe_cast_indexer(key))\n",
      "  File \"pandas/_libs/index.pyx\", line 117, in pandas._libs.index.IndexEngine.get_loc\n",
      "  File \"pandas/_libs/index.pyx\", line 139, in pandas._libs.index.IndexEngine.get_loc\n",
      "  File \"pandas/_libs/hashtable_class_helper.pxi\", line 1265, in pandas._libs.hashtable.PyObjectHashTable.get_item\n",
      "  File \"pandas/_libs/hashtable_class_helper.pxi\", line 1273, in pandas._libs.hashtable.PyObjectHashTable.get_item\n",
      "KeyError: 6\n",
      "\n",
      "During handling of the above exception, another exception occurred:\n",
      "\n",
      "Traceback (most recent call last):\n",
      "  File \"/Users/fauxcomrade/anaconda3/lib/python3.6/site-packages/IPython/core/interactiveshell.py\", line 1828, in showtraceback\n",
      "    stb = value._render_traceback_()\n",
      "AttributeError: 'KeyError' object has no attribute '_render_traceback_'\n",
      "\n",
      "During handling of the above exception, another exception occurred:\n",
      "\n",
      "Traceback (most recent call last):\n",
      "  File \"/Users/fauxcomrade/anaconda3/lib/python3.6/site-packages/IPython/core/interactiveshell.py\", line 2850, in run_ast_nodes\n",
      "    if self.run_code(code, result):\n",
      "  File \"/Users/fauxcomrade/anaconda3/lib/python3.6/site-packages/IPython/core/interactiveshell.py\", line 2927, in run_code\n",
      "    self.showtraceback(running_compiled_code=True)\n",
      "  File \"/Users/fauxcomrade/anaconda3/lib/python3.6/site-packages/IPython/core/interactiveshell.py\", line 1831, in showtraceback\n",
      "    value, tb, tb_offset=tb_offset)\n",
      "  File \"/Users/fauxcomrade/anaconda3/lib/python3.6/site-packages/IPython/core/ultratb.py\", line 1371, in structured_traceback\n",
      "    self, etype, value, tb, tb_offset, number_of_lines_of_context)\n",
      "  File \"/Users/fauxcomrade/anaconda3/lib/python3.6/site-packages/IPython/core/ultratb.py\", line 1279, in structured_traceback\n",
      "    self, etype, value, tb, tb_offset, number_of_lines_of_context\n",
      "  File \"/Users/fauxcomrade/anaconda3/lib/python3.6/site-packages/IPython/core/ultratb.py\", line 1140, in structured_traceback\n",
      "    formatted_exceptions += self.prepare_chained_exception_message(evalue.__cause__)\n",
      "TypeError: must be str, not list\n",
      "\n",
      "During handling of the above exception, another exception occurred:\n",
      "\n",
      "Traceback (most recent call last):\n",
      "  File \"/Users/fauxcomrade/anaconda3/lib/python3.6/site-packages/IPython/core/interactiveshell.py\", line 1828, in showtraceback\n",
      "    stb = value._render_traceback_()\n",
      "AttributeError: 'TypeError' object has no attribute '_render_traceback_'\n",
      "\n",
      "During handling of the above exception, another exception occurred:\n",
      "\n",
      "Traceback (most recent call last):\n",
      "  File \"/Users/fauxcomrade/anaconda3/lib/python3.6/site-packages/IPython/core/ultratb.py\", line 1090, in get_records\n",
      "    return _fixed_getinnerframes(etb, number_of_lines_of_context, tb_offset)\n",
      "  File \"/Users/fauxcomrade/anaconda3/lib/python3.6/site-packages/IPython/core/ultratb.py\", line 311, in wrapped\n",
      "    return f(*args, **kwargs)\n",
      "  File \"/Users/fauxcomrade/anaconda3/lib/python3.6/site-packages/IPython/core/ultratb.py\", line 345, in _fixed_getinnerframes\n",
      "    records = fix_frame_records_filenames(inspect.getinnerframes(etb, context))\n",
      "  File \"/Users/fauxcomrade/anaconda3/lib/python3.6/inspect.py\", line 1483, in getinnerframes\n",
      "    frameinfo = (tb.tb_frame,) + getframeinfo(tb, context)\n",
      "  File \"/Users/fauxcomrade/anaconda3/lib/python3.6/inspect.py\", line 1441, in getframeinfo\n",
      "    filename = getsourcefile(frame) or getfile(frame)\n",
      "  File \"/Users/fauxcomrade/anaconda3/lib/python3.6/inspect.py\", line 696, in getsourcefile\n",
      "    if getattr(getmodule(object, filename), '__loader__', None) is not None:\n",
      "  File \"/Users/fauxcomrade/anaconda3/lib/python3.6/inspect.py\", line 733, in getmodule\n",
      "    if ismodule(module) and hasattr(module, '__file__'):\n",
      "  File \"/Users/fauxcomrade/anaconda3/lib/python3.6/site-packages/py/_vendored_packages/apipkg.py\", line 195, in __getattribute__\n",
      "    return getattr(getmod(), name)\n",
      "  File \"/Users/fauxcomrade/anaconda3/lib/python3.6/site-packages/py/_vendored_packages/apipkg.py\", line 179, in getmod\n",
      "    x = importobj(modpath, None)\n",
      "  File \"/Users/fauxcomrade/anaconda3/lib/python3.6/site-packages/py/_vendored_packages/apipkg.py\", line 69, in importobj\n",
      "    module = __import__(modpath, None, None, ['__doc__'])\n",
      "  File \"/Users/fauxcomrade/anaconda3/lib/python3.6/site-packages/pytest.py\", line 13, in <module>\n",
      "    from _pytest.fixtures import fixture, yield_fixture\n",
      "  File \"/Users/fauxcomrade/anaconda3/lib/python3.6/site-packages/_pytest/fixtures.py\", line 842, in <module>\n",
      "    class FixtureFunctionMarker(object):\n",
      "  File \"/Users/fauxcomrade/anaconda3/lib/python3.6/site-packages/_pytest/fixtures.py\", line 844, in FixtureFunctionMarker\n",
      "    params = attr.ib(convert=attr.converters.optional(tuple))\n",
      "TypeError: attrib() got an unexpected keyword argument 'convert'\n"
     ]
    },
    {
     "ename": "TypeError",
     "evalue": "must be str, not list",
     "output_type": "error",
     "traceback": [
      "\u001b[0;31m---------------------------------------------------------------------------\u001b[0m",
      "\nDuring handling of the above exception, another exception occurred:\n",
      "\nDuring handling of the above exception, another exception occurred:\n",
      "\u001b[0;31mAttributeError\u001b[0m                            Traceback (most recent call last)",
      "\u001b[0;32m~/anaconda3/lib/python3.6/site-packages/IPython/core/interactiveshell.py\u001b[0m in \u001b[0;36mshowtraceback\u001b[0;34m(self, exc_tuple, filename, tb_offset, exception_only, running_compiled_code)\u001b[0m\n\u001b[1;32m   1827\u001b[0m                         \u001b[0;31m# in the engines. This should return a list of strings.\u001b[0m\u001b[0;34m\u001b[0m\u001b[0;34m\u001b[0m\u001b[0m\n\u001b[0;32m-> 1828\u001b[0;31m                         \u001b[0mstb\u001b[0m \u001b[0;34m=\u001b[0m \u001b[0mvalue\u001b[0m\u001b[0;34m.\u001b[0m\u001b[0m_render_traceback_\u001b[0m\u001b[0;34m(\u001b[0m\u001b[0;34m)\u001b[0m\u001b[0;34m\u001b[0m\u001b[0m\n\u001b[0m\u001b[1;32m   1829\u001b[0m                     \u001b[0;32mexcept\u001b[0m \u001b[0mException\u001b[0m\u001b[0;34m:\u001b[0m\u001b[0;34m\u001b[0m\u001b[0m\n",
      "\u001b[0;31mAttributeError\u001b[0m: 'KeyError' object has no attribute '_render_traceback_'",
      "\nDuring handling of the above exception, another exception occurred:\n",
      "\u001b[0;31mTypeError\u001b[0m                                 Traceback (most recent call last)",
      "\u001b[0;32m~/anaconda3/lib/python3.6/site-packages/IPython/core/interactiveshell.py\u001b[0m in \u001b[0;36mrun_code\u001b[0;34m(self, code_obj, result)\u001b[0m\n\u001b[1;32m   2925\u001b[0m             \u001b[0;32mif\u001b[0m \u001b[0mresult\u001b[0m \u001b[0;32mis\u001b[0m \u001b[0;32mnot\u001b[0m \u001b[0;32mNone\u001b[0m\u001b[0;34m:\u001b[0m\u001b[0;34m\u001b[0m\u001b[0m\n\u001b[1;32m   2926\u001b[0m                 \u001b[0mresult\u001b[0m\u001b[0;34m.\u001b[0m\u001b[0merror_in_exec\u001b[0m \u001b[0;34m=\u001b[0m \u001b[0msys\u001b[0m\u001b[0;34m.\u001b[0m\u001b[0mexc_info\u001b[0m\u001b[0;34m(\u001b[0m\u001b[0;34m)\u001b[0m\u001b[0;34m[\u001b[0m\u001b[0;36m1\u001b[0m\u001b[0;34m]\u001b[0m\u001b[0;34m\u001b[0m\u001b[0m\n\u001b[0;32m-> 2927\u001b[0;31m             \u001b[0mself\u001b[0m\u001b[0;34m.\u001b[0m\u001b[0mshowtraceback\u001b[0m\u001b[0;34m(\u001b[0m\u001b[0mrunning_compiled_code\u001b[0m\u001b[0;34m=\u001b[0m\u001b[0;32mTrue\u001b[0m\u001b[0;34m)\u001b[0m\u001b[0;34m\u001b[0m\u001b[0m\n\u001b[0m\u001b[1;32m   2928\u001b[0m         \u001b[0;32melse\u001b[0m\u001b[0;34m:\u001b[0m\u001b[0;34m\u001b[0m\u001b[0m\n\u001b[1;32m   2929\u001b[0m             \u001b[0moutflag\u001b[0m \u001b[0;34m=\u001b[0m \u001b[0;32mFalse\u001b[0m\u001b[0;34m\u001b[0m\u001b[0m\n",
      "\u001b[0;32m~/anaconda3/lib/python3.6/site-packages/IPython/core/interactiveshell.py\u001b[0m in \u001b[0;36mshowtraceback\u001b[0;34m(self, exc_tuple, filename, tb_offset, exception_only, running_compiled_code)\u001b[0m\n\u001b[1;32m   1829\u001b[0m                     \u001b[0;32mexcept\u001b[0m \u001b[0mException\u001b[0m\u001b[0;34m:\u001b[0m\u001b[0;34m\u001b[0m\u001b[0m\n\u001b[1;32m   1830\u001b[0m                         stb = self.InteractiveTB.structured_traceback(etype,\n\u001b[0;32m-> 1831\u001b[0;31m                                             value, tb, tb_offset=tb_offset)\n\u001b[0m\u001b[1;32m   1832\u001b[0m \u001b[0;34m\u001b[0m\u001b[0m\n\u001b[1;32m   1833\u001b[0m                     \u001b[0mself\u001b[0m\u001b[0;34m.\u001b[0m\u001b[0m_showtraceback\u001b[0m\u001b[0;34m(\u001b[0m\u001b[0metype\u001b[0m\u001b[0;34m,\u001b[0m \u001b[0mvalue\u001b[0m\u001b[0;34m,\u001b[0m \u001b[0mstb\u001b[0m\u001b[0;34m)\u001b[0m\u001b[0;34m\u001b[0m\u001b[0m\n",
      "\u001b[0;32m~/anaconda3/lib/python3.6/site-packages/IPython/core/ultratb.py\u001b[0m in \u001b[0;36mstructured_traceback\u001b[0;34m(self, etype, value, tb, tb_offset, number_of_lines_of_context)\u001b[0m\n\u001b[1;32m   1369\u001b[0m         \u001b[0mself\u001b[0m\u001b[0;34m.\u001b[0m\u001b[0mtb\u001b[0m \u001b[0;34m=\u001b[0m \u001b[0mtb\u001b[0m\u001b[0;34m\u001b[0m\u001b[0m\n\u001b[1;32m   1370\u001b[0m         return FormattedTB.structured_traceback(\n\u001b[0;32m-> 1371\u001b[0;31m             self, etype, value, tb, tb_offset, number_of_lines_of_context)\n\u001b[0m\u001b[1;32m   1372\u001b[0m \u001b[0;34m\u001b[0m\u001b[0m\n\u001b[1;32m   1373\u001b[0m \u001b[0;34m\u001b[0m\u001b[0m\n",
      "\u001b[0;32m~/anaconda3/lib/python3.6/site-packages/IPython/core/ultratb.py\u001b[0m in \u001b[0;36mstructured_traceback\u001b[0;34m(self, etype, value, tb, tb_offset, number_of_lines_of_context)\u001b[0m\n\u001b[1;32m   1277\u001b[0m             \u001b[0;31m# Verbose modes need a full traceback\u001b[0m\u001b[0;34m\u001b[0m\u001b[0;34m\u001b[0m\u001b[0m\n\u001b[1;32m   1278\u001b[0m             return VerboseTB.structured_traceback(\n\u001b[0;32m-> 1279\u001b[0;31m                 \u001b[0mself\u001b[0m\u001b[0;34m,\u001b[0m \u001b[0metype\u001b[0m\u001b[0;34m,\u001b[0m \u001b[0mvalue\u001b[0m\u001b[0;34m,\u001b[0m \u001b[0mtb\u001b[0m\u001b[0;34m,\u001b[0m \u001b[0mtb_offset\u001b[0m\u001b[0;34m,\u001b[0m \u001b[0mnumber_of_lines_of_context\u001b[0m\u001b[0;34m\u001b[0m\u001b[0m\n\u001b[0m\u001b[1;32m   1280\u001b[0m             )\n\u001b[1;32m   1281\u001b[0m         \u001b[0;32melse\u001b[0m\u001b[0;34m:\u001b[0m\u001b[0;34m\u001b[0m\u001b[0m\n",
      "\u001b[0;32m~/anaconda3/lib/python3.6/site-packages/IPython/core/ultratb.py\u001b[0m in \u001b[0;36mstructured_traceback\u001b[0;34m(self, etype, evalue, etb, tb_offset, number_of_lines_of_context)\u001b[0m\n\u001b[1;32m   1138\u001b[0m             \u001b[0mexception\u001b[0m \u001b[0;34m=\u001b[0m \u001b[0mself\u001b[0m\u001b[0;34m.\u001b[0m\u001b[0mget_parts_of_chained_exception\u001b[0m\u001b[0;34m(\u001b[0m\u001b[0mevalue\u001b[0m\u001b[0;34m)\u001b[0m\u001b[0;34m\u001b[0m\u001b[0m\n\u001b[1;32m   1139\u001b[0m             \u001b[0;32mif\u001b[0m \u001b[0mexception\u001b[0m\u001b[0;34m:\u001b[0m\u001b[0;34m\u001b[0m\u001b[0m\n\u001b[0;32m-> 1140\u001b[0;31m                 \u001b[0mformatted_exceptions\u001b[0m \u001b[0;34m+=\u001b[0m \u001b[0mself\u001b[0m\u001b[0;34m.\u001b[0m\u001b[0mprepare_chained_exception_message\u001b[0m\u001b[0;34m(\u001b[0m\u001b[0mevalue\u001b[0m\u001b[0;34m.\u001b[0m\u001b[0m__cause__\u001b[0m\u001b[0;34m)\u001b[0m\u001b[0;34m\u001b[0m\u001b[0m\n\u001b[0m\u001b[1;32m   1141\u001b[0m                 \u001b[0metype\u001b[0m\u001b[0;34m,\u001b[0m \u001b[0mevalue\u001b[0m\u001b[0;34m,\u001b[0m \u001b[0metb\u001b[0m \u001b[0;34m=\u001b[0m \u001b[0mexception\u001b[0m\u001b[0;34m\u001b[0m\u001b[0m\n\u001b[1;32m   1142\u001b[0m             \u001b[0;32melse\u001b[0m\u001b[0;34m:\u001b[0m\u001b[0;34m\u001b[0m\u001b[0m\n",
      "\u001b[0;31mTypeError\u001b[0m: must be str, not list"
     ]
    }
   ],
   "source": []
  },
  {
   "cell_type": "code",
   "execution_count": 14,
   "metadata": {},
   "outputs": [
    {
     "name": "stderr",
     "output_type": "stream",
     "text": [
      "ERROR:root:Internal Python error in the inspect module.\n",
      "Below is the traceback from this internal error.\n",
      "\n",
      "ERROR:root:Internal Python error in the inspect module.\n",
      "Below is the traceback from this internal error.\n",
      "\n",
      "ERROR:root:Internal Python error in the inspect module.\n",
      "Below is the traceback from this internal error.\n",
      "\n"
     ]
    },
    {
     "name": "stdout",
     "output_type": "stream",
     "text": [
      "Traceback (most recent call last):\n",
      "  File \"/Users/fauxcomrade/anaconda3/lib/python3.6/site-packages/pandas/core/indexes/base.py\", line 2525, in get_loc\n",
      "    return self._engine.get_loc(key)\n",
      "  File \"pandas/_libs/index.pyx\", line 117, in pandas._libs.index.IndexEngine.get_loc\n",
      "  File \"pandas/_libs/index.pyx\", line 139, in pandas._libs.index.IndexEngine.get_loc\n",
      "  File \"pandas/_libs/hashtable_class_helper.pxi\", line 1265, in pandas._libs.hashtable.PyObjectHashTable.get_item\n",
      "  File \"pandas/_libs/hashtable_class_helper.pxi\", line 1273, in pandas._libs.hashtable.PyObjectHashTable.get_item\n",
      "KeyError: 6\n",
      "\n",
      "During handling of the above exception, another exception occurred:\n",
      "\n",
      "Traceback (most recent call last):\n",
      "  File \"/Users/fauxcomrade/anaconda3/lib/python3.6/site-packages/IPython/core/interactiveshell.py\", line 2910, in run_code\n",
      "    exec(code_obj, self.user_global_ns, self.user_ns)\n",
      "  File \"<ipython-input-14-7c3c43c23d4e>\", line 1, in <module>\n",
      "    df2 =data[data[6].isnull()]\n",
      "  File \"/Users/fauxcomrade/anaconda3/lib/python3.6/site-packages/pandas/core/frame.py\", line 2139, in __getitem__\n",
      "    return self._getitem_column(key)\n",
      "  File \"/Users/fauxcomrade/anaconda3/lib/python3.6/site-packages/pandas/core/frame.py\", line 2146, in _getitem_column\n",
      "    return self._get_item_cache(key)\n",
      "  File \"/Users/fauxcomrade/anaconda3/lib/python3.6/site-packages/pandas/core/generic.py\", line 1842, in _get_item_cache\n",
      "    values = self._data.get(item)\n",
      "  File \"/Users/fauxcomrade/anaconda3/lib/python3.6/site-packages/pandas/core/internals.py\", line 3843, in get\n",
      "    loc = self.items.get_loc(item)\n",
      "  File \"/Users/fauxcomrade/anaconda3/lib/python3.6/site-packages/pandas/core/indexes/base.py\", line 2527, in get_loc\n",
      "    return self._engine.get_loc(self._maybe_cast_indexer(key))\n",
      "  File \"pandas/_libs/index.pyx\", line 117, in pandas._libs.index.IndexEngine.get_loc\n",
      "  File \"pandas/_libs/index.pyx\", line 139, in pandas._libs.index.IndexEngine.get_loc\n",
      "  File \"pandas/_libs/hashtable_class_helper.pxi\", line 1265, in pandas._libs.hashtable.PyObjectHashTable.get_item\n",
      "  File \"pandas/_libs/hashtable_class_helper.pxi\", line 1273, in pandas._libs.hashtable.PyObjectHashTable.get_item\n",
      "KeyError: 6\n",
      "\n",
      "During handling of the above exception, another exception occurred:\n",
      "\n",
      "Traceback (most recent call last):\n",
      "  File \"/Users/fauxcomrade/anaconda3/lib/python3.6/site-packages/IPython/core/interactiveshell.py\", line 1828, in showtraceback\n",
      "    stb = value._render_traceback_()\n",
      "AttributeError: 'KeyError' object has no attribute '_render_traceback_'\n",
      "\n",
      "During handling of the above exception, another exception occurred:\n",
      "\n",
      "Traceback (most recent call last):\n",
      "  File \"/Users/fauxcomrade/anaconda3/lib/python3.6/site-packages/IPython/core/ultratb.py\", line 1090, in get_records\n",
      "    return _fixed_getinnerframes(etb, number_of_lines_of_context, tb_offset)\n",
      "  File \"/Users/fauxcomrade/anaconda3/lib/python3.6/site-packages/IPython/core/ultratb.py\", line 311, in wrapped\n",
      "    return f(*args, **kwargs)\n",
      "  File \"/Users/fauxcomrade/anaconda3/lib/python3.6/site-packages/IPython/core/ultratb.py\", line 345, in _fixed_getinnerframes\n",
      "    records = fix_frame_records_filenames(inspect.getinnerframes(etb, context))\n",
      "  File \"/Users/fauxcomrade/anaconda3/lib/python3.6/inspect.py\", line 1483, in getinnerframes\n",
      "    frameinfo = (tb.tb_frame,) + getframeinfo(tb, context)\n",
      "  File \"/Users/fauxcomrade/anaconda3/lib/python3.6/inspect.py\", line 1441, in getframeinfo\n",
      "    filename = getsourcefile(frame) or getfile(frame)\n",
      "  File \"/Users/fauxcomrade/anaconda3/lib/python3.6/inspect.py\", line 696, in getsourcefile\n",
      "    if getattr(getmodule(object, filename), '__loader__', None) is not None:\n",
      "  File \"/Users/fauxcomrade/anaconda3/lib/python3.6/inspect.py\", line 733, in getmodule\n",
      "    if ismodule(module) and hasattr(module, '__file__'):\n",
      "  File \"/Users/fauxcomrade/anaconda3/lib/python3.6/site-packages/py/_vendored_packages/apipkg.py\", line 195, in __getattribute__\n",
      "    return getattr(getmod(), name)\n",
      "  File \"/Users/fauxcomrade/anaconda3/lib/python3.6/site-packages/py/_vendored_packages/apipkg.py\", line 179, in getmod\n",
      "    x = importobj(modpath, None)\n",
      "  File \"/Users/fauxcomrade/anaconda3/lib/python3.6/site-packages/py/_vendored_packages/apipkg.py\", line 69, in importobj\n",
      "    module = __import__(modpath, None, None, ['__doc__'])\n",
      "  File \"/Users/fauxcomrade/anaconda3/lib/python3.6/site-packages/pytest.py\", line 13, in <module>\n",
      "    from _pytest.fixtures import fixture, yield_fixture\n",
      "  File \"/Users/fauxcomrade/anaconda3/lib/python3.6/site-packages/_pytest/fixtures.py\", line 842, in <module>\n",
      "    class FixtureFunctionMarker(object):\n",
      "  File \"/Users/fauxcomrade/anaconda3/lib/python3.6/site-packages/_pytest/fixtures.py\", line 844, in FixtureFunctionMarker\n",
      "    params = attr.ib(convert=attr.converters.optional(tuple))\n",
      "TypeError: attrib() got an unexpected keyword argument 'convert'\n",
      "Traceback (most recent call last):\n",
      "  File \"/Users/fauxcomrade/anaconda3/lib/python3.6/site-packages/pandas/core/indexes/base.py\", line 2525, in get_loc\n",
      "    return self._engine.get_loc(key)\n",
      "  File \"pandas/_libs/index.pyx\", line 117, in pandas._libs.index.IndexEngine.get_loc\n",
      "  File \"pandas/_libs/index.pyx\", line 139, in pandas._libs.index.IndexEngine.get_loc\n",
      "  File \"pandas/_libs/hashtable_class_helper.pxi\", line 1265, in pandas._libs.hashtable.PyObjectHashTable.get_item\n",
      "  File \"pandas/_libs/hashtable_class_helper.pxi\", line 1273, in pandas._libs.hashtable.PyObjectHashTable.get_item\n",
      "KeyError: 6\n",
      "\n",
      "During handling of the above exception, another exception occurred:\n",
      "\n",
      "Traceback (most recent call last):\n",
      "  File \"/Users/fauxcomrade/anaconda3/lib/python3.6/site-packages/IPython/core/interactiveshell.py\", line 2910, in run_code\n",
      "    exec(code_obj, self.user_global_ns, self.user_ns)\n",
      "  File \"<ipython-input-14-7c3c43c23d4e>\", line 1, in <module>\n",
      "    df2 =data[data[6].isnull()]\n",
      "  File \"/Users/fauxcomrade/anaconda3/lib/python3.6/site-packages/pandas/core/frame.py\", line 2139, in __getitem__\n",
      "    return self._getitem_column(key)\n",
      "  File \"/Users/fauxcomrade/anaconda3/lib/python3.6/site-packages/pandas/core/frame.py\", line 2146, in _getitem_column\n",
      "    return self._get_item_cache(key)\n",
      "  File \"/Users/fauxcomrade/anaconda3/lib/python3.6/site-packages/pandas/core/generic.py\", line 1842, in _get_item_cache\n",
      "    values = self._data.get(item)\n",
      "  File \"/Users/fauxcomrade/anaconda3/lib/python3.6/site-packages/pandas/core/internals.py\", line 3843, in get\n",
      "    loc = self.items.get_loc(item)\n",
      "  File \"/Users/fauxcomrade/anaconda3/lib/python3.6/site-packages/pandas/core/indexes/base.py\", line 2527, in get_loc\n",
      "    return self._engine.get_loc(self._maybe_cast_indexer(key))\n",
      "  File \"pandas/_libs/index.pyx\", line 117, in pandas._libs.index.IndexEngine.get_loc\n",
      "  File \"pandas/_libs/index.pyx\", line 139, in pandas._libs.index.IndexEngine.get_loc\n",
      "  File \"pandas/_libs/hashtable_class_helper.pxi\", line 1265, in pandas._libs.hashtable.PyObjectHashTable.get_item\n",
      "  File \"pandas/_libs/hashtable_class_helper.pxi\", line 1273, in pandas._libs.hashtable.PyObjectHashTable.get_item\n",
      "KeyError: 6\n",
      "\n",
      "During handling of the above exception, another exception occurred:\n",
      "\n",
      "Traceback (most recent call last):\n",
      "  File \"/Users/fauxcomrade/anaconda3/lib/python3.6/site-packages/IPython/core/interactiveshell.py\", line 1828, in showtraceback\n",
      "    stb = value._render_traceback_()\n",
      "AttributeError: 'KeyError' object has no attribute '_render_traceback_'\n",
      "\n",
      "During handling of the above exception, another exception occurred:\n",
      "\n",
      "Traceback (most recent call last):\n",
      "  File \"/Users/fauxcomrade/anaconda3/lib/python3.6/site-packages/IPython/core/interactiveshell.py\", line 2850, in run_ast_nodes\n",
      "    if self.run_code(code, result):\n",
      "  File \"/Users/fauxcomrade/anaconda3/lib/python3.6/site-packages/IPython/core/interactiveshell.py\", line 2927, in run_code\n",
      "    self.showtraceback(running_compiled_code=True)\n",
      "  File \"/Users/fauxcomrade/anaconda3/lib/python3.6/site-packages/IPython/core/interactiveshell.py\", line 1831, in showtraceback\n",
      "    value, tb, tb_offset=tb_offset)\n",
      "  File \"/Users/fauxcomrade/anaconda3/lib/python3.6/site-packages/IPython/core/ultratb.py\", line 1371, in structured_traceback\n",
      "    self, etype, value, tb, tb_offset, number_of_lines_of_context)\n",
      "  File \"/Users/fauxcomrade/anaconda3/lib/python3.6/site-packages/IPython/core/ultratb.py\", line 1279, in structured_traceback\n",
      "    self, etype, value, tb, tb_offset, number_of_lines_of_context\n",
      "  File \"/Users/fauxcomrade/anaconda3/lib/python3.6/site-packages/IPython/core/ultratb.py\", line 1140, in structured_traceback\n",
      "    formatted_exceptions += self.prepare_chained_exception_message(evalue.__cause__)\n",
      "TypeError: must be str, not list\n",
      "\n",
      "During handling of the above exception, another exception occurred:\n",
      "\n",
      "Traceback (most recent call last):\n",
      "  File \"/Users/fauxcomrade/anaconda3/lib/python3.6/site-packages/IPython/core/interactiveshell.py\", line 1828, in showtraceback\n",
      "    stb = value._render_traceback_()\n",
      "AttributeError: 'TypeError' object has no attribute '_render_traceback_'\n",
      "\n",
      "During handling of the above exception, another exception occurred:\n",
      "\n",
      "Traceback (most recent call last):\n",
      "  File \"/Users/fauxcomrade/anaconda3/lib/python3.6/site-packages/IPython/core/ultratb.py\", line 1090, in get_records\n",
      "    return _fixed_getinnerframes(etb, number_of_lines_of_context, tb_offset)\n",
      "  File \"/Users/fauxcomrade/anaconda3/lib/python3.6/site-packages/IPython/core/ultratb.py\", line 311, in wrapped\n",
      "    return f(*args, **kwargs)\n",
      "  File \"/Users/fauxcomrade/anaconda3/lib/python3.6/site-packages/IPython/core/ultratb.py\", line 345, in _fixed_getinnerframes\n",
      "    records = fix_frame_records_filenames(inspect.getinnerframes(etb, context))\n",
      "  File \"/Users/fauxcomrade/anaconda3/lib/python3.6/inspect.py\", line 1483, in getinnerframes\n",
      "    frameinfo = (tb.tb_frame,) + getframeinfo(tb, context)\n",
      "  File \"/Users/fauxcomrade/anaconda3/lib/python3.6/inspect.py\", line 1441, in getframeinfo\n",
      "    filename = getsourcefile(frame) or getfile(frame)\n",
      "  File \"/Users/fauxcomrade/anaconda3/lib/python3.6/inspect.py\", line 696, in getsourcefile\n",
      "    if getattr(getmodule(object, filename), '__loader__', None) is not None:\n",
      "  File \"/Users/fauxcomrade/anaconda3/lib/python3.6/inspect.py\", line 733, in getmodule\n",
      "    if ismodule(module) and hasattr(module, '__file__'):\n",
      "  File \"/Users/fauxcomrade/anaconda3/lib/python3.6/site-packages/py/_vendored_packages/apipkg.py\", line 195, in __getattribute__\n",
      "    return getattr(getmod(), name)\n",
      "  File \"/Users/fauxcomrade/anaconda3/lib/python3.6/site-packages/py/_vendored_packages/apipkg.py\", line 179, in getmod\n",
      "    x = importobj(modpath, None)\n",
      "  File \"/Users/fauxcomrade/anaconda3/lib/python3.6/site-packages/py/_vendored_packages/apipkg.py\", line 69, in importobj\n",
      "    module = __import__(modpath, None, None, ['__doc__'])\n",
      "  File \"/Users/fauxcomrade/anaconda3/lib/python3.6/site-packages/pytest.py\", line 13, in <module>\n",
      "    from _pytest.fixtures import fixture, yield_fixture\n",
      "  File \"/Users/fauxcomrade/anaconda3/lib/python3.6/site-packages/_pytest/fixtures.py\", line 842, in <module>\n",
      "    class FixtureFunctionMarker(object):\n",
      "  File \"/Users/fauxcomrade/anaconda3/lib/python3.6/site-packages/_pytest/fixtures.py\", line 844, in FixtureFunctionMarker\n",
      "    params = attr.ib(convert=attr.converters.optional(tuple))\n",
      "TypeError: attrib() got an unexpected keyword argument 'convert'\n",
      "Traceback (most recent call last):\n",
      "  File \"/Users/fauxcomrade/anaconda3/lib/python3.6/site-packages/pandas/core/indexes/base.py\", line 2525, in get_loc\n",
      "    return self._engine.get_loc(key)\n",
      "  File \"pandas/_libs/index.pyx\", line 117, in pandas._libs.index.IndexEngine.get_loc\n",
      "  File \"pandas/_libs/index.pyx\", line 139, in pandas._libs.index.IndexEngine.get_loc\n",
      "  File \"pandas/_libs/hashtable_class_helper.pxi\", line 1265, in pandas._libs.hashtable.PyObjectHashTable.get_item\n",
      "  File \"pandas/_libs/hashtable_class_helper.pxi\", line 1273, in pandas._libs.hashtable.PyObjectHashTable.get_item\n",
      "KeyError: 6\n",
      "\n",
      "During handling of the above exception, another exception occurred:\n",
      "\n",
      "Traceback (most recent call last):\n",
      "  File \"/Users/fauxcomrade/anaconda3/lib/python3.6/site-packages/IPython/core/interactiveshell.py\", line 2910, in run_code\n",
      "    exec(code_obj, self.user_global_ns, self.user_ns)\n",
      "  File \"<ipython-input-14-7c3c43c23d4e>\", line 1, in <module>\n",
      "    df2 =data[data[6].isnull()]\n",
      "  File \"/Users/fauxcomrade/anaconda3/lib/python3.6/site-packages/pandas/core/frame.py\", line 2139, in __getitem__\n",
      "    return self._getitem_column(key)\n",
      "  File \"/Users/fauxcomrade/anaconda3/lib/python3.6/site-packages/pandas/core/frame.py\", line 2146, in _getitem_column\n",
      "    return self._get_item_cache(key)\n",
      "  File \"/Users/fauxcomrade/anaconda3/lib/python3.6/site-packages/pandas/core/generic.py\", line 1842, in _get_item_cache\n",
      "    values = self._data.get(item)\n",
      "  File \"/Users/fauxcomrade/anaconda3/lib/python3.6/site-packages/pandas/core/internals.py\", line 3843, in get\n",
      "    loc = self.items.get_loc(item)\n",
      "  File \"/Users/fauxcomrade/anaconda3/lib/python3.6/site-packages/pandas/core/indexes/base.py\", line 2527, in get_loc\n",
      "    return self._engine.get_loc(self._maybe_cast_indexer(key))\n",
      "  File \"pandas/_libs/index.pyx\", line 117, in pandas._libs.index.IndexEngine.get_loc\n",
      "  File \"pandas/_libs/index.pyx\", line 139, in pandas._libs.index.IndexEngine.get_loc\n",
      "  File \"pandas/_libs/hashtable_class_helper.pxi\", line 1265, in pandas._libs.hashtable.PyObjectHashTable.get_item\n",
      "  File \"pandas/_libs/hashtable_class_helper.pxi\", line 1273, in pandas._libs.hashtable.PyObjectHashTable.get_item\n",
      "KeyError: 6\n",
      "\n",
      "During handling of the above exception, another exception occurred:\n",
      "\n",
      "Traceback (most recent call last):\n",
      "  File \"/Users/fauxcomrade/anaconda3/lib/python3.6/site-packages/IPython/core/interactiveshell.py\", line 1828, in showtraceback\n",
      "    stb = value._render_traceback_()\n",
      "AttributeError: 'KeyError' object has no attribute '_render_traceback_'\n",
      "\n",
      "During handling of the above exception, another exception occurred:\n",
      "\n",
      "Traceback (most recent call last):\n",
      "  File \"/Users/fauxcomrade/anaconda3/lib/python3.6/site-packages/IPython/core/interactiveshell.py\", line 2850, in run_ast_nodes\n",
      "    if self.run_code(code, result):\n",
      "  File \"/Users/fauxcomrade/anaconda3/lib/python3.6/site-packages/IPython/core/interactiveshell.py\", line 2927, in run_code\n",
      "    self.showtraceback(running_compiled_code=True)\n",
      "  File \"/Users/fauxcomrade/anaconda3/lib/python3.6/site-packages/IPython/core/interactiveshell.py\", line 1831, in showtraceback\n",
      "    value, tb, tb_offset=tb_offset)\n",
      "  File \"/Users/fauxcomrade/anaconda3/lib/python3.6/site-packages/IPython/core/ultratb.py\", line 1371, in structured_traceback\n",
      "    self, etype, value, tb, tb_offset, number_of_lines_of_context)\n",
      "  File \"/Users/fauxcomrade/anaconda3/lib/python3.6/site-packages/IPython/core/ultratb.py\", line 1279, in structured_traceback\n",
      "    self, etype, value, tb, tb_offset, number_of_lines_of_context\n",
      "  File \"/Users/fauxcomrade/anaconda3/lib/python3.6/site-packages/IPython/core/ultratb.py\", line 1140, in structured_traceback\n",
      "    formatted_exceptions += self.prepare_chained_exception_message(evalue.__cause__)\n",
      "TypeError: must be str, not list\n",
      "\n",
      "During handling of the above exception, another exception occurred:\n",
      "\n",
      "Traceback (most recent call last):\n",
      "  File \"/Users/fauxcomrade/anaconda3/lib/python3.6/site-packages/IPython/core/interactiveshell.py\", line 1828, in showtraceback\n",
      "    stb = value._render_traceback_()\n",
      "AttributeError: 'TypeError' object has no attribute '_render_traceback_'\n",
      "\n",
      "During handling of the above exception, another exception occurred:\n",
      "\n",
      "Traceback (most recent call last):\n",
      "  File \"/Users/fauxcomrade/anaconda3/lib/python3.6/site-packages/IPython/core/ultratb.py\", line 1090, in get_records\n",
      "    return _fixed_getinnerframes(etb, number_of_lines_of_context, tb_offset)\n",
      "  File \"/Users/fauxcomrade/anaconda3/lib/python3.6/site-packages/IPython/core/ultratb.py\", line 311, in wrapped\n",
      "    return f(*args, **kwargs)\n",
      "  File \"/Users/fauxcomrade/anaconda3/lib/python3.6/site-packages/IPython/core/ultratb.py\", line 345, in _fixed_getinnerframes\n",
      "    records = fix_frame_records_filenames(inspect.getinnerframes(etb, context))\n",
      "  File \"/Users/fauxcomrade/anaconda3/lib/python3.6/inspect.py\", line 1483, in getinnerframes\n",
      "    frameinfo = (tb.tb_frame,) + getframeinfo(tb, context)\n",
      "  File \"/Users/fauxcomrade/anaconda3/lib/python3.6/inspect.py\", line 1441, in getframeinfo\n",
      "    filename = getsourcefile(frame) or getfile(frame)\n",
      "  File \"/Users/fauxcomrade/anaconda3/lib/python3.6/inspect.py\", line 696, in getsourcefile\n",
      "    if getattr(getmodule(object, filename), '__loader__', None) is not None:\n",
      "  File \"/Users/fauxcomrade/anaconda3/lib/python3.6/inspect.py\", line 733, in getmodule\n",
      "    if ismodule(module) and hasattr(module, '__file__'):\n",
      "  File \"/Users/fauxcomrade/anaconda3/lib/python3.6/site-packages/py/_vendored_packages/apipkg.py\", line 195, in __getattribute__\n",
      "    return getattr(getmod(), name)\n",
      "  File \"/Users/fauxcomrade/anaconda3/lib/python3.6/site-packages/py/_vendored_packages/apipkg.py\", line 179, in getmod\n",
      "    x = importobj(modpath, None)\n",
      "  File \"/Users/fauxcomrade/anaconda3/lib/python3.6/site-packages/py/_vendored_packages/apipkg.py\", line 69, in importobj\n",
      "    module = __import__(modpath, None, None, ['__doc__'])\n",
      "  File \"/Users/fauxcomrade/anaconda3/lib/python3.6/site-packages/pytest.py\", line 13, in <module>\n",
      "    from _pytest.fixtures import fixture, yield_fixture\n",
      "  File \"/Users/fauxcomrade/anaconda3/lib/python3.6/site-packages/_pytest/fixtures.py\", line 842, in <module>\n",
      "    class FixtureFunctionMarker(object):\n",
      "  File \"/Users/fauxcomrade/anaconda3/lib/python3.6/site-packages/_pytest/fixtures.py\", line 844, in FixtureFunctionMarker\n",
      "    params = attr.ib(convert=attr.converters.optional(tuple))\n",
      "TypeError: attrib() got an unexpected keyword argument 'convert'\n"
     ]
    },
    {
     "ename": "TypeError",
     "evalue": "must be str, not list",
     "output_type": "error",
     "traceback": [
      "\u001b[0;31m---------------------------------------------------------------------------\u001b[0m",
      "\nDuring handling of the above exception, another exception occurred:\n",
      "\nDuring handling of the above exception, another exception occurred:\n",
      "\u001b[0;31mAttributeError\u001b[0m                            Traceback (most recent call last)",
      "\u001b[0;32m~/anaconda3/lib/python3.6/site-packages/IPython/core/interactiveshell.py\u001b[0m in \u001b[0;36mshowtraceback\u001b[0;34m(self, exc_tuple, filename, tb_offset, exception_only, running_compiled_code)\u001b[0m\n\u001b[1;32m   1827\u001b[0m                         \u001b[0;31m# in the engines. This should return a list of strings.\u001b[0m\u001b[0;34m\u001b[0m\u001b[0;34m\u001b[0m\u001b[0m\n\u001b[0;32m-> 1828\u001b[0;31m                         \u001b[0mstb\u001b[0m \u001b[0;34m=\u001b[0m \u001b[0mvalue\u001b[0m\u001b[0;34m.\u001b[0m\u001b[0m_render_traceback_\u001b[0m\u001b[0;34m(\u001b[0m\u001b[0;34m)\u001b[0m\u001b[0;34m\u001b[0m\u001b[0m\n\u001b[0m\u001b[1;32m   1829\u001b[0m                     \u001b[0;32mexcept\u001b[0m \u001b[0mException\u001b[0m\u001b[0;34m:\u001b[0m\u001b[0;34m\u001b[0m\u001b[0m\n",
      "\u001b[0;31mAttributeError\u001b[0m: 'KeyError' object has no attribute '_render_traceback_'",
      "\nDuring handling of the above exception, another exception occurred:\n",
      "\u001b[0;31mTypeError\u001b[0m                                 Traceback (most recent call last)",
      "\u001b[0;32m~/anaconda3/lib/python3.6/site-packages/IPython/core/interactiveshell.py\u001b[0m in \u001b[0;36mrun_code\u001b[0;34m(self, code_obj, result)\u001b[0m\n\u001b[1;32m   2925\u001b[0m             \u001b[0;32mif\u001b[0m \u001b[0mresult\u001b[0m \u001b[0;32mis\u001b[0m \u001b[0;32mnot\u001b[0m \u001b[0;32mNone\u001b[0m\u001b[0;34m:\u001b[0m\u001b[0;34m\u001b[0m\u001b[0m\n\u001b[1;32m   2926\u001b[0m                 \u001b[0mresult\u001b[0m\u001b[0;34m.\u001b[0m\u001b[0merror_in_exec\u001b[0m \u001b[0;34m=\u001b[0m \u001b[0msys\u001b[0m\u001b[0;34m.\u001b[0m\u001b[0mexc_info\u001b[0m\u001b[0;34m(\u001b[0m\u001b[0;34m)\u001b[0m\u001b[0;34m[\u001b[0m\u001b[0;36m1\u001b[0m\u001b[0;34m]\u001b[0m\u001b[0;34m\u001b[0m\u001b[0m\n\u001b[0;32m-> 2927\u001b[0;31m             \u001b[0mself\u001b[0m\u001b[0;34m.\u001b[0m\u001b[0mshowtraceback\u001b[0m\u001b[0;34m(\u001b[0m\u001b[0mrunning_compiled_code\u001b[0m\u001b[0;34m=\u001b[0m\u001b[0;32mTrue\u001b[0m\u001b[0;34m)\u001b[0m\u001b[0;34m\u001b[0m\u001b[0m\n\u001b[0m\u001b[1;32m   2928\u001b[0m         \u001b[0;32melse\u001b[0m\u001b[0;34m:\u001b[0m\u001b[0;34m\u001b[0m\u001b[0m\n\u001b[1;32m   2929\u001b[0m             \u001b[0moutflag\u001b[0m \u001b[0;34m=\u001b[0m \u001b[0;32mFalse\u001b[0m\u001b[0;34m\u001b[0m\u001b[0m\n",
      "\u001b[0;32m~/anaconda3/lib/python3.6/site-packages/IPython/core/interactiveshell.py\u001b[0m in \u001b[0;36mshowtraceback\u001b[0;34m(self, exc_tuple, filename, tb_offset, exception_only, running_compiled_code)\u001b[0m\n\u001b[1;32m   1829\u001b[0m                     \u001b[0;32mexcept\u001b[0m \u001b[0mException\u001b[0m\u001b[0;34m:\u001b[0m\u001b[0;34m\u001b[0m\u001b[0m\n\u001b[1;32m   1830\u001b[0m                         stb = self.InteractiveTB.structured_traceback(etype,\n\u001b[0;32m-> 1831\u001b[0;31m                                             value, tb, tb_offset=tb_offset)\n\u001b[0m\u001b[1;32m   1832\u001b[0m \u001b[0;34m\u001b[0m\u001b[0m\n\u001b[1;32m   1833\u001b[0m                     \u001b[0mself\u001b[0m\u001b[0;34m.\u001b[0m\u001b[0m_showtraceback\u001b[0m\u001b[0;34m(\u001b[0m\u001b[0metype\u001b[0m\u001b[0;34m,\u001b[0m \u001b[0mvalue\u001b[0m\u001b[0;34m,\u001b[0m \u001b[0mstb\u001b[0m\u001b[0;34m)\u001b[0m\u001b[0;34m\u001b[0m\u001b[0m\n",
      "\u001b[0;32m~/anaconda3/lib/python3.6/site-packages/IPython/core/ultratb.py\u001b[0m in \u001b[0;36mstructured_traceback\u001b[0;34m(self, etype, value, tb, tb_offset, number_of_lines_of_context)\u001b[0m\n\u001b[1;32m   1369\u001b[0m         \u001b[0mself\u001b[0m\u001b[0;34m.\u001b[0m\u001b[0mtb\u001b[0m \u001b[0;34m=\u001b[0m \u001b[0mtb\u001b[0m\u001b[0;34m\u001b[0m\u001b[0m\n\u001b[1;32m   1370\u001b[0m         return FormattedTB.structured_traceback(\n\u001b[0;32m-> 1371\u001b[0;31m             self, etype, value, tb, tb_offset, number_of_lines_of_context)\n\u001b[0m\u001b[1;32m   1372\u001b[0m \u001b[0;34m\u001b[0m\u001b[0m\n\u001b[1;32m   1373\u001b[0m \u001b[0;34m\u001b[0m\u001b[0m\n",
      "\u001b[0;32m~/anaconda3/lib/python3.6/site-packages/IPython/core/ultratb.py\u001b[0m in \u001b[0;36mstructured_traceback\u001b[0;34m(self, etype, value, tb, tb_offset, number_of_lines_of_context)\u001b[0m\n\u001b[1;32m   1277\u001b[0m             \u001b[0;31m# Verbose modes need a full traceback\u001b[0m\u001b[0;34m\u001b[0m\u001b[0;34m\u001b[0m\u001b[0m\n\u001b[1;32m   1278\u001b[0m             return VerboseTB.structured_traceback(\n\u001b[0;32m-> 1279\u001b[0;31m                 \u001b[0mself\u001b[0m\u001b[0;34m,\u001b[0m \u001b[0metype\u001b[0m\u001b[0;34m,\u001b[0m \u001b[0mvalue\u001b[0m\u001b[0;34m,\u001b[0m \u001b[0mtb\u001b[0m\u001b[0;34m,\u001b[0m \u001b[0mtb_offset\u001b[0m\u001b[0;34m,\u001b[0m \u001b[0mnumber_of_lines_of_context\u001b[0m\u001b[0;34m\u001b[0m\u001b[0m\n\u001b[0m\u001b[1;32m   1280\u001b[0m             )\n\u001b[1;32m   1281\u001b[0m         \u001b[0;32melse\u001b[0m\u001b[0;34m:\u001b[0m\u001b[0;34m\u001b[0m\u001b[0m\n",
      "\u001b[0;32m~/anaconda3/lib/python3.6/site-packages/IPython/core/ultratb.py\u001b[0m in \u001b[0;36mstructured_traceback\u001b[0;34m(self, etype, evalue, etb, tb_offset, number_of_lines_of_context)\u001b[0m\n\u001b[1;32m   1138\u001b[0m             \u001b[0mexception\u001b[0m \u001b[0;34m=\u001b[0m \u001b[0mself\u001b[0m\u001b[0;34m.\u001b[0m\u001b[0mget_parts_of_chained_exception\u001b[0m\u001b[0;34m(\u001b[0m\u001b[0mevalue\u001b[0m\u001b[0;34m)\u001b[0m\u001b[0;34m\u001b[0m\u001b[0m\n\u001b[1;32m   1139\u001b[0m             \u001b[0;32mif\u001b[0m \u001b[0mexception\u001b[0m\u001b[0;34m:\u001b[0m\u001b[0;34m\u001b[0m\u001b[0m\n\u001b[0;32m-> 1140\u001b[0;31m                 \u001b[0mformatted_exceptions\u001b[0m \u001b[0;34m+=\u001b[0m \u001b[0mself\u001b[0m\u001b[0;34m.\u001b[0m\u001b[0mprepare_chained_exception_message\u001b[0m\u001b[0;34m(\u001b[0m\u001b[0mevalue\u001b[0m\u001b[0;34m.\u001b[0m\u001b[0m__cause__\u001b[0m\u001b[0;34m)\u001b[0m\u001b[0;34m\u001b[0m\u001b[0m\n\u001b[0m\u001b[1;32m   1141\u001b[0m                 \u001b[0metype\u001b[0m\u001b[0;34m,\u001b[0m \u001b[0mevalue\u001b[0m\u001b[0;34m,\u001b[0m \u001b[0metb\u001b[0m \u001b[0;34m=\u001b[0m \u001b[0mexception\u001b[0m\u001b[0;34m\u001b[0m\u001b[0m\n\u001b[1;32m   1142\u001b[0m             \u001b[0;32melse\u001b[0m\u001b[0;34m:\u001b[0m\u001b[0;34m\u001b[0m\u001b[0m\n",
      "\u001b[0;31mTypeError\u001b[0m: must be str, not list"
     ]
    }
   ],
   "source": [
    "df2 =data[data[6].isnull()]\n",
    "df2.head()\n"
   ]
  },
  {
   "cell_type": "code",
   "execution_count": null,
   "metadata": {},
   "outputs": [],
   "source": [
    "df2.shape"
   ]
  },
  {
   "cell_type": "code",
   "execution_count": null,
   "metadata": {},
   "outputs": [],
   "source": [
    "\n",
    "df3 = df2[df2[0].str.isnumeric()]\n",
    "df3.head()"
   ]
  },
  {
   "cell_type": "code",
   "execution_count": null,
   "metadata": {},
   "outputs": [],
   "source": [
    "df3.shape"
   ]
  },
  {
   "cell_type": "code",
   "execution_count": null,
   "metadata": {},
   "outputs": [],
   "source": [
    "df3.insert(1,\"month\",np.nan)\n",
    "df3.columns = ['index', 0, 1, 2, 3, 4, 5, 6,7]\n",
    "df3.head()"
   ]
  },
  {
   "cell_type": "code",
   "execution_count": null,
   "metadata": {},
   "outputs": [],
   "source": [
    "df4 = df2[df2[0].apply(lambda x: not x.isnumeric())]\n",
    "\n",
    "df4.insert(1,\"month\",np.nan)\n",
    "df4.insert(2,\"day\",np.nan)\n",
    "df4.columns =['index',0, 1, 2, 3, 4,5,6,7,8]\n",
    "df4.shape"
   ]
  },
  {
   "cell_type": "code",
   "execution_count": null,
   "metadata": {},
   "outputs": [],
   "source": [
    "df4.head()"
   ]
  },
  {
   "cell_type": "code",
   "execution_count": null,
   "metadata": {},
   "outputs": [],
   "source": [
    "frames = [df1,df3,df4]\n",
    "result = pd.concat(frames).sort_values(by=['index'])\n",
    "result.head()"
   ]
  },
  {
   "cell_type": "code",
   "execution_count": null,
   "metadata": {},
   "outputs": [],
   "source": [
    "result = result.fillna(method='ffill')\n",
    "result = result.drop([\"index\",7,8],1)\n",
    "result.head()"
   ]
  },
  {
   "cell_type": "code",
   "execution_count": null,
   "metadata": {},
   "outputs": [],
   "source": [
    "columns = ['Month', 'Date', 'Title', 'Director', 'Cast', 'Genre',\"Ref\"]\n",
    "result.columns = columns\n",
    "result = result.drop(0,0)\n",
    "result = result.drop(\"Ref\",1)\n",
    "\n",
    "result.head()\n"
   ]
  },
  {
   "cell_type": "code",
   "execution_count": null,
   "metadata": {},
   "outputs": [],
   "source": [
    "release_date =  result.iloc[:,0].apply(lambda x: x[:3]).map(str) + \" \" + result.iloc[:,1] + \" \" + year\n",
    "release_date = release_date.apply(lambda x:convert2date(x))\n",
    "result.insert(0,'release_date',release_date)\n",
    "result =result.drop([\"Month\",\"Date\"],1)\n",
    "result"
   ]
  },
  {
   "cell_type": "code",
   "execution_count": null,
   "metadata": {},
   "outputs": [],
   "source": [
    "result.shape"
   ]
  },
  {
   "cell_type": "code",
   "execution_count": 4,
   "metadata": {},
   "outputs": [],
   "source": [
    "url2 = \"https://www.imdb.com/search/title/?title_type=feature&primary_language=ml&view=simple&sort=alpha,asc&start=1\"\n",
    "url2 = requests.get(url2).text\n",
    "soup = BeautifulSoup(url2,\"lxml\")"
   ]
  },
  {
   "cell_type": "code",
   "execution_count": 5,
   "metadata": {},
   "outputs": [],
   "source": [
    "title= soup.find_all(\"div\", {\"class\":\"col-title\"})\n"
   ]
  },
  {
   "cell_type": "code",
   "execution_count": 7,
   "metadata": {},
   "outputs": [
    {
     "name": "stdout",
     "output_type": "stream",
     "text": [
      "/title/tt4570696/\n",
      "/title/tt3686130/\n",
      "/title/tt6260318/\n",
      "/title/tt3995348/\n",
      "/title/tt3885676/\n",
      "/title/tt5471518/\n",
      "/title/tt3668280/\n",
      "/title/tt2545176/\n",
      "/title/tt2928360/\n",
      "/title/tt6005838/\n",
      "/title/tt7692434/\n",
      "/title/tt9034602/\n",
      "/title/tt10366954/\n",
      "/title/tt6363436/\n",
      "/title/tt3506970/\n",
      "/title/tt1886449/\n",
      "/title/tt11064868/\n",
      "/title/tt1332676/\n",
      "/title/tt4594194/\n",
      "/title/tt9146254/\n",
      "/title/tt8116540/\n",
      "/title/tt2363047/\n",
      "/title/tt1639312/\n",
      "/title/tt9006564/\n",
      "/title/tt2866804/\n",
      "/title/tt4887400/\n",
      "/title/tt8081646/\n",
      "/title/tt2731098/\n",
      "/title/tt0400076/\n",
      "/title/tt9877340/\n",
      "/title/tt3005920/\n",
      "/title/tt10638304/\n",
      "/title/tt10337582/\n",
      "/title/tt7683264/\n",
      "/title/tt4242016/\n",
      "/title/tt3661988/\n",
      "/title/tt5059698/\n",
      "/title/tt4118740/\n",
      "/title/tt2779840/\n",
      "/title/tt8180482/\n",
      "/title/tt4125324/\n",
      "/title/tt10473174/\n",
      "/title/tt10909266/\n",
      "/title/tt10137480/\n",
      "/title/tt2956300/\n",
      "/title/tt10137620/\n",
      "/title/tt8216296/\n",
      "/title/tt0352131/\n",
      "/title/tt0257356/\n",
      "/title/tt0247907/\n"
     ]
    }
   ],
   "source": [
    "for div in title:\n",
    "    print(div.find('a')['href'])"
   ]
  },
  {
   "cell_type": "code",
   "execution_count": null,
   "metadata": {},
   "outputs": [],
   "source": []
  }
 ],
 "metadata": {
  "kernelspec": {
   "display_name": "Python 3",
   "language": "python",
   "name": "python3"
  },
  "language_info": {
   "codemirror_mode": {
    "name": "ipython",
    "version": 3
   },
   "file_extension": ".py",
   "mimetype": "text/x-python",
   "name": "python",
   "nbconvert_exporter": "python",
   "pygments_lexer": "ipython3",
   "version": "3.6.6"
  }
 },
 "nbformat": 4,
 "nbformat_minor": 2
}
